<robot name="fourr_planar">

  <link name="base_link">
    <visual>
      <geometry>
        <cylinder length="0.1" radius="0.2"/>
      </geometry>
    </visual>
  </link>
  
  <link name="link1">
    <visual>
      <geometry>
        <box size="7 0.4 0.1"/>
      </geometry>
      <origin rpy="0 0 0" xyz="3.5 0 0"/>
    </visual>  
  </link>
  
  <link name="link2">
    <visual>
      <geometry>
        <box size="7 0.4 0.1"/>
      </geometry>
      <origin rpy="0 0 0" xyz="3.5 0 0"/>
    </visual>
  </link>
  
  <link name="link3">
    <visual>
      <geometry>
        <box size="4.0 0.4 0.1"/>
      </geometry>
      <origin rpy="0 0 0" xyz="2 0 0"/>
    </visual>  
  </link>
  
  <link name="link4">
    <visual>
      <geometry>
        <box size="1.5 0.4 0.1"/>
      </geometry>
      <origin rpy="0 0 0" xyz="0.75 0 0"/>
    </visual>  
  </link>
  
  <link name="link5"/>

  <joint name="joint1" type="continuous">
    <parent link="base_link"/>
    <child link="link1"/>
    <origin xyz="0 0 0.1" rpy="0 0 0"/>
    <axis xyz="0 0 1"/>
    <limit effort="1000.0" velocity ="2.0"/>
  </joint>

  <joint name="joint2" type="continuous">
    <parent link="link1"/>
    <child link="link2"/>
    <origin xyz="7 0 0.1" rpy="0 0 0"/>
    <axis xyz="0 0 1"/>
    <limit effort="1000.0" velocity ="2.0"/>
  </joint>

  <joint name="joint3" type="continuous">
    <parent link="link2"/>
    <child link="link3"/>
    <origin xyz="7 0 0.1" rpy="0 0 0"/>
    <axis xyz="0 0 1"/>
    <limit effort="1000.0" velocity ="2.0"/>
  </joint>

  <joint name="joint4" type="continuous">
    <parent link="link3"/>
    <child link="link4"/>
    <origin xyz="4 0 0.1" rpy="0 0 0"/>
    <axis xyz="0 0 1"/>
    <limit effort="1000.0" velocity ="2.0"/>
  </joint>
  
  <joint name="joint5" type="fixed">
    <parent link="link4"/>
    <child link="link5"/>
    <origin xyz="1.5 0 0" rpy="0 0 0"/>
    <axis xyz="0 0 0"/>
  </joint>

</robot>
